2024-05-13 13:34:37,460 - apscheduler.scheduler - INFO - Scheduler started
2024-05-13 13:34:46,434 - __main__ - INFO - User e1essar_vi sent message: hi
2024-05-13 13:34:55,333 - telegram.ext.updater - INFO - Received signal 2 (SIGINT), stopping...
2024-05-13 13:34:55,333 - apscheduler.scheduler - INFO - Scheduler has been shut down
2024-05-13 13:35:14,378 - apscheduler.scheduler - INFO - Scheduler started
2024-05-13 13:35:40,052 - apscheduler.scheduler - INFO - Scheduler started
2024-05-13 13:35:40,905 - telegram.ext.updater - INFO - Received signal 2 (SIGINT), stopping...
2024-05-13 13:35:40,905 - apscheduler.scheduler - INFO - Scheduler has been shut down
2024-05-13 14:16:17,216 - apscheduler.scheduler - INFO - Scheduler started
2024-05-13 14:16:33,927 - __main__ - INFO - get_release requested
2024-05-13 14:16:39,303 - telegram.ext.updater - INFO - Received signal 2 (SIGINT), stopping...
2024-05-13 14:16:39,303 - apscheduler.scheduler - INFO - Scheduler has been shut down
2024-05-13 14:16:51,231 - telegram.ext.updater - WARNING - Exiting immediately!
2024-05-13 14:18:49,378 - apscheduler.scheduler - INFO - Scheduler started
2024-05-13 14:18:57,204 - __main__ - INFO - get_w requested
2024-05-13 14:19:18,212 - telegram.ext.dispatcher - ERROR - No error handlers are registered, logging exception.
Traceback (most recent call last):
  File "C:\Users\Igor\AppData\Local\Packages\PythonSoftwareFoundation.Python.3.12_qbz5n2kfra8p0\LocalCache\local-packages\Python312\site-packages\telegram\ext\dispatcher.py", line 555, in process_update
    handler.handle_update(update, self, check, context)
  File "C:\Users\Igor\AppData\Local\Packages\PythonSoftwareFoundation.Python.3.12_qbz5n2kfra8p0\LocalCache\local-packages\Python312\site-packages\telegram\ext\conversationhandler.py", line 626, in handle_update
    new_state = handler.handle_update(update, dispatcher, check_result, context)
                ^^^^^^^^^^^^^^^^^^^^^^^^^^^^^^^^^^^^^^^^^^^^^^^^^^^^^^^^^^^^^^^^
  File "C:\Users\Igor\AppData\Local\Packages\PythonSoftwareFoundation.Python.3.12_qbz5n2kfra8p0\LocalCache\local-packages\Python312\site-packages\telegram\ext\handler.py", line 198, in handle_update
    return self.callback(update, context)
           ^^^^^^^^^^^^^^^^^^^^^^^^^^^^^^
  File "C:\Users\Igor\Desktop\PT_START_DEVOPS\devops_bot\bot\bot.py", line 238, in get_w
    client.connect(hostname=host, username=username, password=password, port=port)
  File "C:\Users\Igor\AppData\Local\Packages\PythonSoftwareFoundation.Python.3.12_qbz5n2kfra8p0\LocalCache\local-packages\Python312\site-packages\paramiko\client.py", line 386, in connect
    sock.connect(addr)
TimeoutError: [WinError 10060] A connection attempt failed because the connected party did not properly respond after a period of time, or established connection failed because connected host has failed to respond
2024-05-13 14:19:28,879 - __main__ - INFO - get_release requested
2024-05-13 14:19:40,940 - telegram.ext.updater - INFO - Received signal 2 (SIGINT), stopping...
2024-05-13 14:19:40,940 - apscheduler.scheduler - INFO - Scheduler has been shut down
2024-05-13 14:19:49,882 - telegram.ext.dispatcher - ERROR - No error handlers are registered, logging exception.
Traceback (most recent call last):
  File "C:\Users\Igor\AppData\Local\Packages\PythonSoftwareFoundation.Python.3.12_qbz5n2kfra8p0\LocalCache\local-packages\Python312\site-packages\telegram\ext\dispatcher.py", line 555, in process_update
    handler.handle_update(update, self, check, context)
  File "C:\Users\Igor\AppData\Local\Packages\PythonSoftwareFoundation.Python.3.12_qbz5n2kfra8p0\LocalCache\local-packages\Python312\site-packages\telegram\ext\conversationhandler.py", line 626, in handle_update
    new_state = handler.handle_update(update, dispatcher, check_result, context)
                ^^^^^^^^^^^^^^^^^^^^^^^^^^^^^^^^^^^^^^^^^^^^^^^^^^^^^^^^^^^^^^^^
  File "C:\Users\Igor\AppData\Local\Packages\PythonSoftwareFoundation.Python.3.12_qbz5n2kfra8p0\LocalCache\local-packages\Python312\site-packages\telegram\ext\handler.py", line 198, in handle_update
    return self.callback(update, context)
           ^^^^^^^^^^^^^^^^^^^^^^^^^^^^^^
  File "C:\Users\Igor\Desktop\PT_START_DEVOPS\devops_bot\bot\bot.py", line 118, in get_release
    client.connect(hostname=host, username=username, password=password, port=port)
  File "C:\Users\Igor\AppData\Local\Packages\PythonSoftwareFoundation.Python.3.12_qbz5n2kfra8p0\LocalCache\local-packages\Python312\site-packages\paramiko\client.py", line 386, in connect
    sock.connect(addr)
TimeoutError: [WinError 10060] A connection attempt failed because the connected party did not properly respond after a period of time, or established connection failed because connected host has failed to respond
2024-05-13 14:20:54,402 - apscheduler.scheduler - INFO - Scheduler started
2024-05-13 14:20:59,147 - __main__ - INFO - get_release requested
2024-05-13 14:20:59,162 - paramiko.transport - INFO - Connected (version 2.0, client OpenSSH_8.9p1)
2024-05-13 14:20:59,284 - paramiko.transport - INFO - Authentication (password) successful!
2024-05-13 14:20:59,285 - root - INFO - Connected via ssh to 192.168.31.24
2024-05-13 14:21:04,070 - telegram.ext.updater - INFO - Received signal 2 (SIGINT), stopping...
2024-05-13 14:21:04,070 - apscheduler.scheduler - INFO - Scheduler has been shut down
2024-05-13 19:39:13,687 - apscheduler.scheduler - INFO - Scheduler started
2024-05-13 19:39:19,985 - __main__ - INFO - User e1essar_vi sent message: ты мразь
2024-05-13 19:39:26,602 - __main__ - INFO - get_release requested
2024-05-13 19:39:26,616 - paramiko.transport - INFO - Connected (version 2.0, client OpenSSH_8.9p1)
2024-05-13 19:39:26,743 - paramiko.transport - INFO - Authentication (password) successful!
2024-05-13 19:39:26,743 - root - INFO - Connected via ssh to 192.168.43.157
2024-05-13 19:39:36,105 - telegram.ext.updater - INFO - Received signal 2 (SIGINT), stopping...
2024-05-13 19:39:36,105 - apscheduler.scheduler - INFO - Scheduler has been shut down
2024-05-13 20:05:42,479 - apscheduler.scheduler - INFO - Scheduler started
2024-05-13 20:05:50,630 - root - ERROR - Error in PostgreSQL: connection to server at "192.168.43.157", port 5432 failed: Connection refused (0x0000274D/10061)
	Is the server running on that host and accepting TCP/IP connections?

2024-05-13 20:05:50,631 - telegram.ext.dispatcher - ERROR - No error handlers are registered, logging exception.
Traceback (most recent call last):
  File "C:\Users\Igor\AppData\Local\Packages\PythonSoftwareFoundation.Python.3.12_qbz5n2kfra8p0\LocalCache\local-packages\Python312\site-packages\telegram\ext\dispatcher.py", line 555, in process_update
    handler.handle_update(update, self, check, context)
  File "C:\Users\Igor\AppData\Local\Packages\PythonSoftwareFoundation.Python.3.12_qbz5n2kfra8p0\LocalCache\local-packages\Python312\site-packages\telegram\ext\conversationhandler.py", line 626, in handle_update
    new_state = handler.handle_update(update, dispatcher, check_result, context)
                ^^^^^^^^^^^^^^^^^^^^^^^^^^^^^^^^^^^^^^^^^^^^^^^^^^^^^^^^^^^^^^^^
  File "C:\Users\Igor\AppData\Local\Packages\PythonSoftwareFoundation.Python.3.12_qbz5n2kfra8p0\LocalCache\local-packages\Python312\site-packages\telegram\ext\handler.py", line 198, in handle_update
    return self.callback(update, context)
           ^^^^^^^^^^^^^^^^^^^^^^^^^^^^^^
  File "C:\Users\Igor\Desktop\PT_START_DEVOPS\devops_bot\bot\bot.py", line 433, in get_email
    if connection is not None:
       ^^^^^^^^^^
UnboundLocalError: cannot access local variable 'connection' where it is not associated with a value
2024-05-13 20:06:08,568 - telegram.ext.updater - INFO - Received signal 2 (SIGINT), stopping...
2024-05-13 20:06:08,568 - apscheduler.scheduler - INFO - Scheduler has been shut down
